Workbook

Sheet Overview
A1: SELF-DIRECTED PRACTICE PROJECT. All suppliers, invoices, amounts, employees and approvers are fictional and created for skills practice. This is not professional accounts payable experience.
A2: AP Register and Overdue Payables: Practice Project
A3: Supplier invoice processing, expense coding, payment tracking, duplicate checks, overdue report
A5: Purpose | B5: Practice the daily steps of an accounts payable (AP) clerk on a small, fictional data set, and show the control checks I would run before an invoice is paid.
A6: What is inside | B6: AP_Register (28 invoices), Expense_Claims (12 employee claims), Overdue_Report (aging, by supplier, action list, chart), Checks (what each flag does and the seeded test cases), Process_Note (the workflow), Lists (suppliers, terms, categories, tax codes).
A7: As-of date | B7: Set in AP_Register cell D3 (blue). Currently 2026-10-09. Change it and every check and the overdue report recalculates. Type =TODAY() for a live report.
A8: Colour code | B8: Blue text = typed input. Black = formula. Green = link to another sheet. Red cells in the check columns = exceptions to review.
A9: Fictional data | B9: Supplier names, invoice numbers, PO numbers, amounts, approvers and employees are invented. Any resemblance to a real company is coincidental. GST at 5% is used for illustration; real tax treatment would be confirmed with an accountant.
A10: What this is not | B10: It is not professional AP experience and does not use any real employer data. It is a self-directed exercise to practice and show the method.
A11: Headline results (as of 2026-10-09) | B11: See the Overdue_Report sheet. Results are formulas, so they update with the register.

Sheet AP_Register
A1: SELF-DIRECTED PRACTICE PROJECT. All suppliers, invoices, amounts, employees and approvers are fictional and created for skills practice. This is not professional accounts payable experience.
A2: AP Register
A3: As-of date: | D3: 46304
A5: AP # | B5: Supplier invoice no. | C5: Supplier | D5: Invoice date | E5: Terms (days) | F5: Due date | G5: PO number | H5: Description | I5: Expense category | J5: GL code | K5: Billable to client? | L5: Job / cost centre | M5: Net amount ($) | N5: Tax code | O5: Tax billed ($) | P5: Tax expected ($) | Q5: Total billed ($) | R5: Supporting docs (Y/N) | S5: Approval status | T5: Approver | U5: Payment status | V5: Payment date | W5: Amount paid ($) | X5: Balance owing ($) | Y5: Exact duplicate | Z5: Probable duplicate | AA5: Tax variance | AB5: Missing docs | AC5: Paid without approval | AD5: Date check | AE5: Exceptions (count) | AF5: Days overdue | AG5: Overdue key (helper)
A6: AP-0001 | B6: CCF-0871 | C6: Cinder Creek Fabrication Ltd. | D6: 46181 | E6: =INDEX(Lists!$B$5:$B$13,MATCH(C6,Lists!$A$5:$A$13,0)) -> 30 | F6: =D6+E6 -> 46211 | G6: PO-4310 | H6: Fabricated pipe spools, lot 12 | I6: Subcontractor Services | J6: =INDEX(Lists!$E$5:$E$14,MATCH(I6,Lists!$D$5:$D$14,0)) -> 5200 | K6: =INDEX(Lists!$F$5:$F$14,MATCH(I6,Lists!$D$5:$D$14,0)) -> Y | L6: J-102 | M6: 14250 | N6: GST5 | O6: 712.5 | P6: =ROUND(M6*INDEX(Lists!$I$5:$I$6,MATCH(N6,Lists!$H$5:$H$6,0)),2) -> 712.5 | Q6: =M6+O6 -> 14962.5 | R6: Y | S6: On Hold | T6: A. Carter | U6: Unpaid | W6: 0 | X6: =IF(S6="Rejected",0,Q6-W6) -> 14962.5 | Y6: =IF(COUNTIFS($C$6:C6,C6,$B$6:B6,B6)>1,"DUPLICATE","") | Z6: =IF(AND(Y6="",COUNTIFS($C$6:C6,C6,$Q$6:Q6,Q6,$D$6:D6,">="&(D6-14),$D$6:D6,"<="&(D6+14))>1),"CHECK","") | AA6: =IF(ABS(O6-P6)>0.01,"TAX?","") | AB6: =IF(R6<>"Y","NO DOCS","") | AC6: =IF(AND(U6="Paid",S6<>"Approved"),"CONTROL","") | AD6: =IF(OR(D6>$D$3,F6<D6),"DATE?","") | AE6: =SUMPRODUCT(--(LEN(Y6:AD6)>0)) -> 0 | AF6: =IF(AND(X6>0,F6<$D$3),$D$3-F6,0) -> 93 | AG6: =IF(AF6>0,AF6+ROW()/10000,"") -> 93.0006
A7: AP-0002 | B7: RSS-20418 | C7: Ridgeline Safety Supply Ltd. | D7: 46211 | E7: =INDEX(Lists!$B$5:$B$13,MATCH(C7,Lists!$A$5:$A$13,0)) -> 30 | F7: =D7+E7 -> 46241 | G7: PO-4401 | H7: Hi-vis vests and gloves | I7: Safety Supplies | J7: =INDEX(Lists!$E$5:$E$14,MATCH(I7,Lists!$D$5:$D$14,0)) -> 6100 | K7: =INDEX(Lists!$F$5:$F$14,MATCH(I7,Lists!$D$5:$D$14,0)) -> N | M7: 1240 | N7: GST5 | O7: 62 | P7: =ROUND(M7*INDEX(Lists!$I$5:$I$6,MATCH(N7,Lists!$H$5:$H$6,0)),2) -> 62 | Q7: =M7+O7 -> 1302 | R7: Y | S7: Approved | T7: J. Nguyen | U7: Paid | V7: 46240 | W7: 1302 | X7: =IF(S7="Rejected",0,Q7-W7) -> 0 | Y7: =IF(COUNTIFS($C$6:C7,C7,$B$6:B7,B7)>1,"DUPLICATE","") | Z7: =IF(AND(Y7="",COUNTIFS($C$6:C7,C7,$Q$6:Q7,Q7,$D$6:D7,">="&(D7-14),$D$6:D7,"<="&(D7+14))>1),"CHECK","") | AA7: =IF(ABS(O7-P7)>0.01,"TAX?","") | AB7: =IF(R7<>"Y","NO DOCS","") | AC7: =IF(AND(U7="Paid",S7<>"Approved"),"CONTROL","") | AD7: =IF(OR(D7>$D$3,F7<D7),"DATE?","") | AE7: =SUMPRODUCT(--(LEN(Y7:AD7)>0)) -> 0 | AF7: =IF(AND(X7>0,F7<$D$3),$D$3-F7,0) -> 0 | AG7: =IF(AF7>0,AF7+ROW()/10000,"")
A8: AP-0003 | B8: BV-5532 | C8: Bow Valley Office Products Ltd. | D8: 46212 | E8: =INDEX(Lists!$B$5:$B$13,MATCH(C8,Lists!$A$5:$A$13,0)) -> 30 | F8: =D8+E8 -> 46242 | G8: PO-4405 | H8: Printer paper and toner | I8: Office Supplies | J8: =INDEX(Lists!$E$5:$E$14,MATCH(I8,Lists!$D$5:$D$14,0)) -> 6200 | K8: =INDEX(Lists!$F$5:$F$14,MATCH(I8,Lists!$D$5:$D$14,0)) -> N | M8: 386.4 | N8: GST5 | O8: 19.32 | P8: =ROUND(M8*INDEX(Lists!$I$5:$I$6,MATCH(N8,Lists!$H$5:$H$6,0)),2) -> 19.32 | Q8: =M8+O8 -> 405.72 | R8: Y | S8: Approved | T8: J. Nguyen | U8: Paid | V8: 46241 | W8: 405.72 | X8: =IF(S8="Rejected",0,Q8-W8) -> -5.6843419e-14 | Y8: =IF(COUNTIFS($C$6:C8,C8,$B$6:B8,B8)>1,"DUPLICATE","") | Z8: =IF(AND(Y8="",COUNTIFS($C$6:C8,C8,$Q$6:Q8,Q8,$D$6:D8,">="&(D8-14),$D$6:D8,"<="&(D8+14))>1),"CHECK","") | AA8: =IF(ABS(O8-P8)>0.01,"TAX?","") | AB8: =IF(R8<>"Y","NO DOCS","") | AC8: =IF(AND(U8="Paid",S8<>"Approved"),"CONTROL","") | AD8: =IF(OR(D8>$D$3,F8<D8),"DATE?","") | AE8: =SUMPRODUCT(--(LEN(Y8:AD8)>0)) -> 0 | AF8: =IF(AND(X8>0,F8<$D$3),$D$3-F8,0) -> 0 | AG8: =IF(AF8>0,AF8+ROW()/10000,"")
A9: AP-0004 | B9: PF-88120 | C9: Prairie Fuel & Lube Inc. | D9: 46217 | E9: =INDEX(Lists!$B$5:$B$13,MATCH(C9,Lists!$A$5:$A$13,0)) -> 15 | F9: =D9+E9 -> 46232 | G9: PO-4412 | H9: Diesel, site generators | I9: Fuel & Lubricants | J9: =INDEX(Lists!$E$5:$E$14,MATCH(I9,Lists!$D$5:$D$14,0)) -> 5400 | K9: =INDEX(Lists!$F$5:$F$14,MATCH(I9,Lists!$D$5:$D$14,0)) -> Y | L9: J-101 | M9: 3120 | N9: GST5 | O9: 156 | P9: =ROUND(M9*INDEX(Lists!$I$5:$I$6,MATCH(N9,Lists!$H$5:$H$6,0)),2) -> 156 | Q9: =M9+O9 -> 3276 | R9: Y | S9: Approved | T9: R. Singh | U9: Paid | V9: 46232 | W9: 3276 | X9: =IF(S9="Rejected",0,Q9-W9) -> 0 | Y9: =IF(COUNTIFS($C$6:C9,C9,$B$6:B9,B9)>1,"DUPLICATE","") | Z9: =IF(AND(Y9="",COUNTIFS($C$6:C9,C9,$Q$6:Q9,Q9,$D$6:D9,">="&(D9-14),$D$6:D9,"<="&(D9+14))>1),"CHECK","") | AA9: =IF(ABS(O9-P9)>0.01,"TAX?","") | AB9: =IF(R9<>"Y","NO DOCS","") | AC9: =IF(AND(U9="Paid",S9<>"Approved"),"CONTROL","") | AD9: =IF(OR(D9>$D$3,F9<D9),"DATE?","") | AE9: =SUMPRODUCT(--(LEN(Y9:AD9)>0)) -> 0 | AF9: =IF(AND(X9>0,F9<$D$3),$D$3-F9,0) -> 0 | AG9: =IF(AF9>0,AF9+ROW()/10000,"")
A10: AP-0005 | B10: FER-3307 | C10: Foothills Equipment Rentals Ltd. | D10: 46223 | E10: =INDEX(Lists!$B$5:$B$13,MATCH(C10,Lists!$A$5:$A$13,0)) -> 45 | F10: =D10+E10 -> 46268 | G10: PO-4420 | H10: Telehandler rental, 3 weeks | I10: Equipment Rental (Job) | J10: =INDEX(Lists!$E$5:$E$14,MATCH(I10,Lists!$D$5:$D$14,0)) -> 5300 | K10: =INDEX(Lists!$F$5:$F$14,MATCH(I10,Lists!$D$5:$D$14,0)) -> Y | L10: J-103 | M10: 8400 | N10: GST5 | O10: 420 | P10: =ROUND(M10*INDEX(Lists!$I$5:$I$6,MATCH(N10,Lists!$H$5:$H$6,0)),2) -> 420 | Q10: =M10+O10 -> 8820 | R10: Y | S10: Approved | T10: A. Carter | U10: Unpaid | W10: 0 | X10: =IF(S10="Rejected",0,Q10-W10) -> 8820 | Y10: =IF(COUNTIFS($C$6:C10,C10,$B$6:B10,B10)>1,"DUPLICATE","") | Z10: =IF(AND(Y10="",COUNTIFS($C$6:C10,C10,$Q$6:Q10,Q10,$D$6:D10,">="&(D10-14),$D$6:D10,"<="&(D10+14))>1),"CHECK","") | AA10: =IF(ABS(O10-P10)>0.01,"TAX?","") | AB10: =IF(R10<>"Y","NO DOCS","") | AC10: =IF(AND(U10="Paid",S10<>"Approved"),"CONTROL","") | AD10: =IF(OR(D10>$D$3,F10<D10),"DATE?","") | AE10: =SUMPRODUCT(--(LEN(Y10:AD10)>0)) -> 0 | AF10: =IF(AND(X10>0,F10<$D$3),$D$3-F10,0) -> 36 | AG10: =IF(AF10>0,AF10+ROW()/10000,"") -> 36.001
A11: AP-0006 | B11: CCF-0902 | C11: Cinder Creek Fabrication Ltd. | D11: 46213 | E11: =INDEX(Lists!$B$5:$B$13,MATCH(C11,Lists!$A$5:$A$13,0)) -> 30 | F11: =D11+E11 -> 46243 | G11: PO-4398 | H11: Pressure vessel repair | I11: Subcontractor Services | J11: =INDEX(Lists!$E$5:$E$14,MATCH(I11,Lists!$D$5:$D$14,0)) -> 5200 | K11: =INDEX(Lists!$F$5:$F$14,MATCH(I11,Lists!$D$5:$D$14,0)) -> Y | L11: J-102 | M11: 9800 | N11: GST5 | O11: 490 | P11: =ROUND(M11*INDEX(Lists!$I$5:$I$6,MATCH(N11,Lists!$H$5:$H$6,0)),2) -> 490 | Q11: =M11+O11 -> 10290 | R11: Y | S11: On Hold | T11: A. Carter | U11: Unpaid | W11: 0 | X11: =IF(S11="Rejected",0,Q11-W11) -> 10290 | Y11: =IF(COUNTIFS($C$6:C11,C11,$B$6:B11,B11)>1,"DUPLICATE","") | Z11: =IF(AND(Y11="",COUNTIFS($C$6:C11,C11,$Q$6:Q11,Q11,$D$6:D11,">="&(D11-14),$D$6:D11,"<="&(D11+14))>1),"CHECK","") | AA11: =IF(ABS(O11-P11)>0.01,"TAX?","") | AB11: =IF(R11<>"Y","NO DOCS","") | AC11: =IF(AND(U11="Paid",S11<>"Approved"),"CONTROL","") | AD11: =IF(OR(D11>$D$3,F11<D11),"DATE?","") | AE11: =SUMPRODUCT(--(LEN(Y11:AD11)>0)) -> 0 | AF11: =IF(AND(X11>0,F11<$D$3),$D$3-F11,0) -> 61 | AG11: =IF(AF11>0,AF11+ROW()/10000,"") -> 61.0011
A12: AP-0007 | B12: SCF-1190 | C12: Summit Courier & Freight Ltd. | D12: 46225 | E12: =INDEX(Lists!$B$5:$B$13,MATCH(C12,Lists!$A$5:$A$13,0)) -> 15 | F12: =D12+E12 -> 46240 | G12: PO-4425 | H12: Freight, valve shipment | I12: Courier & Freight | J12: =INDEX(Lists!$E$5:$E$14,MATCH(I12,Lists!$D$5:$D$14,0)) -> 6400 | K12: =INDEX(Lists!$F$5:$F$14,MATCH(I12,Lists!$D$5:$D$14,0)) -> N | L12: J-101 | M12: 642.5 | N12: GST5 | O12: 32.13 | P12: =ROUND(M12*INDEX(Lists!$I$5:$I$6,MATCH(N12,Lists!$H$5:$H$6,0)),2) -> 32.13 | Q12: =M12+O12 -> 674.63 | R12: Y | S12: Approved | T12: R. Singh | U12: Paid | V12: 46239 | W12: 674.63 | X12: =IF(S12="Rejected",0,Q12-W12) -> 0 | Y12: =IF(COUNTIFS($C$6:C12,C12,$B$6:B12,B12)>1,"DUPLICATE","") | Z12: =IF(AND(Y12="",COUNTIFS($C$6:C12,C12,$Q$6:Q12,Q12,$D$6:D12,">="&(D12-14),$D$6:D12,"<="&(D12+14))>1),"CHECK","") | AA12: =IF(ABS(O12-P12)>0.01,"TAX?","") | AB12: =IF(R12<>"Y","NO DOCS","") | AC12: =IF(AND(U12="Paid",S12<>"Approved"),"CONTROL","") | AD12: =IF(OR(D12>$D$3,F12<D12),"DATE?","") | AE12: =SUMPRODUCT(--(LEN(Y12:AD12)>0)) -> 0 | AF12: =IF(AND(X12>0,F12<$D$3),$D$3-F12,0) -> 0 | AG12: =IF(AF12>0,AF12+ROW()/10000,"")
A13: AP-0008 | B13: RSS-20431 | C13: Ridgeline Safety Supply Ltd. | D13: 46227 | E13: =INDEX(Lists!$B$5:$B$13,MATCH(C13,Lists!$A$5:$A$13,0)) -> 30 | F13: =D13+E13 -> 46257 | G13: PO-4430 | H13: Fall arrest harnesses (6) | I13: Safety Supplies | J13: =INDEX(Lists!$E$5:$E$14,MATCH(I13,Lists!$D$5:$D$14,0)) -> 6100 | K13: =INDEX(Lists!$F$5:$F$14,MATCH(I13,Lists!$D$5:$D$14,0)) -> N | M13: 2175 | N13: GST5 | O13: 108.75 | P13: =ROUND(M13*INDEX(Lists!$I$5:$I$6,MATCH(N13,Lists!$H$5:$H$6,0)),2) -> 108.75 | Q13: =M13+O13 -> 2283.75 | R13: Y | S13: Approved | T13: J. Nguyen | U13: Paid | V13: 46255 | W13: 2283.75 | X13: =IF(S13="Rejected",0,Q13-W13) -> 0 | Y13: =IF(COUNTIFS($C$6:C13,C13,$B$6:B13,B13)>1,"DUPLICATE","") | Z13: =IF(AND(Y13="",COUNTIFS($C$6:C13,C13,$Q$6:Q13,Q13,$D$6:D13,">="&(D13-14),$D$6:D13,"<="&(D13+14))>1),"CHECK","") | AA13: =IF(ABS(O13-P13)>0.01,"TAX?","") | AB13: =IF(R13<>"Y","NO DOCS","") | AC13: =IF(AND(U13="Paid",S13<>"Approved"),"CONTROL","") | AD13: =IF(OR(D13>$D$3,F13<D13),"DATE?","") | AE13: =SUMPRODUCT(--(LEN(Y13:AD13)>0)) -> 0 | AF13: =IF(AND(X13>0,F13<$D$3),$D$3-F13,0) -> 0 | AG13: =IF(AF13>0,AF13+ROW()/10000,"")
A14: AP-0009 | B14: CJ-3377 | C14: Clearwater Janitorial Ltd. | D14: 46231 | E14: =INDEX(Lists!$B$5:$B$13,MATCH(C14,Lists!$A$5:$A$13,0)) -> 30 | F14: =D14+E14 -> 46261 | G14: PO-4433 | H14: Janitorial service, July | I14: Janitorial & Facilities | J14: =INDEX(Lists!$E$5:$E$14,MATCH(I14,Lists!$D$5:$D$14,0)) -> 6500 | K14: =INDEX(Lists!$F$5:$F$14,MATCH(I14,Lists!$D$5:$D$14,0)) -> N | M14: 1795 | N14: GST5 | O14: 89.75 | P14: =ROUND(M14*INDEX(Lists!$I$5:$I$6,MATCH(N14,Lists!$H$5:$H$6,0)),2) -> 89.75 | Q14: =M14+O14 -> 1884.75 | R14: Y | S14: Approved | T14: J. Nguyen | U14: Paid | V14: 46259 | W14: 1884.75 | X14: =IF(S14="Rejected",0,Q14-W14) -> 0 | Y14: =IF(COUNTIFS($C$6:C14,C14,$B$6:B14,B14)>1,"DUPLICATE","") | Z14: =IF(AND(Y14="",COUNTIFS($C$6:C14,C14,$Q$6:Q14,Q14,$D$6:D14,">="&(D14-14),$D$6:D14,"<="&(D14+14))>1),"CHECK","") | AA14: =IF(ABS(O14-P14)>0.01,"TAX?","") | AB14: =IF(R14<>"Y","NO DOCS","") | AC14: =IF(AND(U14="Paid",S14<>"Approved"),"CONTROL","") | AD14: =IF(OR(D14>$D$3,F14<D14),"DATE?","") | AE14: =SUMPRODUCT(--(LEN(Y14:AD14)>0)) -> 0 | AF14: =IF(AND(X14>0,F14<$D$3),$D$3-F14,0) -> 0 | AG14: =IF(AF14>0,AF14+ROW()/10000,"")
A15: AP-0010 | B15: SCF-1190 | C15: Summit Courier & Freight Ltd. | D15: 46232 | E15: =INDEX(Lists!$B$5:$B$13,MATCH(C15,Lists!$A$5:$A$13,0)) -> 15 | F15: =D15+E15 -> 46247 | G15: PO-4425 | H15: Freight, valve shipment | I15: Courier & Freight | J15: =INDEX(Lists!$E$5:$E$14,MATCH(I15,Lists!$D$5:$D$14,0)) -> 6400 | K15: =INDEX(Lists!$F$5:$F$14,MATCH(I15,Lists!$D$5:$D$14,0)) -> N | L15: J-101 | M15: 642.5 | N15: GST5 | O15: 32.13 | P15: =ROUND(M15*INDEX(Lists!$I$5:$I$6,MATCH(N15,Lists!$H$5:$H$6,0)),2) -> 32.13 | Q15: =M15+O15 -> 674.63 | R15: Y | S15: Pending | T15: R. Singh | U15: Unpaid | W15: 0 | X15: =IF(S15="Rejected",0,Q15-W15) -> 674.63 | Y15: =IF(COUNTIFS($C$6:C15,C15,$B$6:B15,B15)>1,"DUPLICATE","") -> DUPLICATE | Z15: =IF(AND(Y15="",COUNTIFS($C$6:C15,C15,$Q$6:Q15,Q15,$D$6:D15,">="&(D15-14),$D$6:D15,"<="&(D15+14))>1),"CHECK","") | AA15: =IF(ABS(O15-P15)>0.01,"TAX?","") | AB15: =IF(R15<>"Y","NO DOCS","") | AC15: =IF(AND(U15="Paid",S15<>"Approved"),"CONTROL","") | AD15: =IF(OR(D15>$D$3,F15<D15),"DATE?","") | AE15: =SUMPRODUCT(--(LEN(Y15:AD15)>0)) -> 1 | AF15: =IF(AND(X15>0,F15<$D$3),$D$3-F15,0) -> 57 | AG15: =IF(AF15>0,AF15+ROW()/10000,"") -> 57.0015
A16: AP-0011 | B16: CCF-0915 | C16: Cinder Creek Fabrication Ltd. | D16: 46231 | E16: =INDEX(Lists!$B$5:$B$13,MATCH(C16,Lists!$A$5:$A$13,0)) -> 30 | F16: =D16+E16 -> 46261 | G16: PO-4436 | H16: Structural steel, platform | I16: Job Materials | J16: =INDEX(Lists!$E$5:$E$14,MATCH(I16,Lists!$D$5:$D$14,0)) -> 5100 | K16: =INDEX(Lists!$F$5:$F$14,MATCH(I16,Lists!$D$5:$D$14,0)) -> Y | L16: J-103 | M16: 11300 | N16: GST5 | O16: 565 | P16: =ROUND(M16*INDEX(Lists!$I$5:$I$6,MATCH(N16,Lists!$H$5:$H$6,0)),2) -> 565 | Q16: =M16+O16 -> 11865 | R16: N | S16: Approved | T16: A. Carter | U16: Unpaid | W16: 0 | X16: =IF(S16="Rejected",0,Q16-W16) -> 11865 | Y16: =IF(COUNTIFS($C$6:C16,C16,$B$6:B16,B16)>1,"DUPLICATE","") | Z16: =IF(AND(Y16="",COUNTIFS($C$6:C16,C16,$Q$6:Q16,Q16,$D$6:D16,">="&(D16-14),$D$6:D16,"<="&(D16+14))>1),"CHECK","") | AA16: =IF(ABS(O16-P16)>0.01,"TAX?","") | AB16: =IF(R16<>"Y","NO DOCS","") -> NO DOCS | AC16: =IF(AND(U16="Paid",S16<>"Approved"),"CONTROL","") | AD16: =IF(OR(D16>$D$3,F16<D16),"DATE?","") | AE16: =SUMPRODUCT(--(LEN(Y16:AD16)>0)) -> 1 | AF16: =IF(AND(X16>0,F16<$D$3),$D$3-F16,0) -> 43 | AG16: =IF(AF16>0,AF16+ROW()/10000,"") -> 43.0016
A17: AP-0012 | B17: CJ-3402 | C17: Clearwater Janitorial Ltd. | D17: 46239 | E17: =INDEX(Lists!$B$5:$B$13,MATCH(C17,Lists!$A$5:$A$13,0)) -> 30 | F17: =D17+E17 -> 46269 | G17: PO-4441 | H17: Janitorial service, August | I17: Janitorial & Facilities | J17: =INDEX(Lists!$E$5:$E$14,MATCH(I17,Lists!$D$5:$D$14,0)) -> 6500 | K17: =INDEX(Lists!$F$5:$F$14,MATCH(I17,Lists!$D$5:$D$14,0)) -> N | M17: 1850 | N17: GST5 | O17: 92.5 | P17: =ROUND(M17*INDEX(Lists!$I$5:$I$6,MATCH(N17,Lists!$H$5:$H$6,0)),2) -> 92.5 | Q17: =M17+O17 -> 1942.5 | R17: Y | S17: Pending | T17: J. Nguyen | U17: Unpaid | W17: 0 | X17: =IF(S17="Rejected",0,Q17-W17) -> 1942.5 | Y17: =IF(COUNTIFS($C$6:C17,C17,$B$6:B17,B17)>1,"DUPLICATE","") | Z17: =IF(AND(Y17="",COUNTIFS($C$6:C17,C17,$Q$6:Q17,Q17,$D$6:D17,">="&(D17-14),$D$6:D17,"<="&(D17+14))>1),"CHECK","") | AA17: =IF(ABS(O17-P17)>0.01,"TAX?","") | AB17: =IF(R17<>"Y","NO DOCS","") | AC17: =IF(AND(U17="Paid",S17<>"Approved"),"CONTROL","") | AD17: =IF(OR(D17>$D$3,F17<D17),"DATE?","") | AE17: =SUMPRODUCT(--(LEN(Y17:AD17)>0)) -> 0 | AF17: =IF(AND(X17>0,F17<$D$3),$D$3-F17,0) -> 35 | AG17: =IF(AF17>0,AF17+ROW()/10000,"") -> 35.0017
A18: AP-0013 | B18: NG-7710 | C18: Northgate IT Services Inc. | D18: 46240 | E18: =INDEX(Lists!$B$5:$B$13,MATCH(C18,Lists!$A$5:$A$13,0)) -> 30 | F18: =D18+E18 -> 46270 | G18: PO-4443 | H18: Timekeeping software, 25 seats | I18: IT & Software | J18: =INDEX(Lists!$E$5:$E$14,MATCH(I18,Lists!$D$5:$D$14,0)) -> 6300 | K18: =INDEX(Lists!$F$5:$F$14,MATCH(I18,Lists!$D$5:$D$14,0)) -> N | M18: 2400 | N18: GST5 | O18: 120 | P18: =ROUND(M18*INDEX(Lists!$I$5:$I$6,MATCH(N18,Lists!$H$5:$H$6,0)),2) -> 120 | Q18: =M18+O18 -> 2520 | R18: Y | S18: Rejected | T18: R. Singh | U18: Unpaid | W18: 0 | X18: =IF(S18="Rejected",0,Q18-W18) -> 0 | Y18: =IF(COUNTIFS($C$6:C18,C18,$B$6:B18,B18)>1,"DUPLICATE","") | Z18: =IF(AND(Y18="",COUNTIFS($C$6:C18,C18,$Q$6:Q18,Q18,$D$6:D18,">="&(D18-14),$D$6:D18,"<="&(D18+14))>1),"CHECK","") | AA18: =IF(ABS(O18-P18)>0.01,"TAX?","") | AB18: =IF(R18<>"Y","NO DOCS","") | AC18: =IF(AND(U18="Paid",S18<>"Approved"),"CONTROL","") | AD18: =IF(OR(D18>$D$3,F18<D18),"DATE?","") | AE18: =SUMPRODUCT(--(LEN(Y18:AD18)>0)) -> 0 | AF18: =IF(AND(X18>0,F18<$D$3),$D$3-F18,0) -> 0 | AG18: =IF(AF18>0,AF18+ROW()/10000,"")
A19: AP-0014 | B19: RSS-20466 | C19: Ridgeline Safety Supply Ltd. | D19: 46248 | E19: =INDEX(Lists!$B$5:$B$13,MATCH(C19,Lists!$A$5:$A$13,0)) -> 30 | F19: =D19+E19 -> 46278 | G19: PO-4452 | H19: Gas monitors, calibration gas | I19: Job Materials | J19: =INDEX(Lists!$E$5:$E$14,MATCH(I19,Lists!$D$5:$D$14,0)) -> 5100 | K19: =INDEX(Lists!$F$5:$F$14,MATCH(I19,Lists!$D$5:$D$14,0)) -> Y | L19: J-104 | M19: 4620 | N19: GST5 | O19: 231 | P19: =ROUND(M19*INDEX(Lists!$I$5:$I$6,MATCH(N19,Lists!$H$5:$H$6,0)),2) -> 231 | Q19: =M19+O19 -> 4851 | R19: Y | S19: Approved | T19: J. Nguyen | U19: Unpaid | W19: 0 | X19: =IF(S19="Rejected",0,Q19-W19) -> 4851 | Y19: =IF(COUNTIFS($C$6:C19,C19,$B$6:B19,B19)>1,"DUPLICATE","") | Z19: =IF(AND(Y19="",COUNTIFS($C$6:C19,C19,$Q$6:Q19,Q19,$D$6:D19,">="&(D19-14),$D$6:D19,"<="&(D19+14))>1),"CHECK","") | AA19: =IF(ABS(O19-P19)>0.01,"TAX?","") | AB19: =IF(R19<>"Y","NO DOCS","") | AC19: =IF(AND(U19="Paid",S19<>"Approved"),"CONTROL","") | AD19: =IF(OR(D19>$D$3,F19<D19),"DATE?","") | AE19: =SUMPRODUCT(--(LEN(Y19:AD19)>0)) -> 0 | AF19: =IF(AND(X19>0,F19<$D$3),$D$3-F19,0) -> 26 | AG19: =IF(AF19>0,AF19+ROW()/10000,"") -> 26.0019
A20: AP-0015 | B20: FER-3341 | C20: Foothills Equipment Rentals Ltd. | D20: 46246 | E20: =INDEX(Lists!$B$5:$B$13,MATCH(C20,Lists!$A$5:$A$13,0)) -> 45 | F20: =D20+E20 -> 46291 | G20: PO-4450 | H20: Scissor lift rental, 2 weeks | I20: Equipment Rental (Job) | J20: =INDEX(Lists!$E$5:$E$14,MATCH(I20,Lists!$D$5:$D$14,0)) -> 5300 | K20: =INDEX(Lists!$F$5:$F$14,MATCH(I20,Lists!$D$5:$D$14,0)) -> Y | L20: J-104 | M20: 2000 | N20: GST5 | O20: 120 | P20: =ROUND(M20*INDEX(Lists!$I$5:$I$6,MATCH(N20,Lists!$H$5:$H$6,0)),2) -> 100 | Q20: =M20+O20 -> 2120 | R20: Y | S20: Approved | T20: A. Carter | U20: Paid | V20: 46290 | W20: 2120 | X20: =IF(S20="Rejected",0,Q20-W20) -> 0 | Y20: =IF(COUNTIFS($C$6:C20,C20,$B$6:B20,B20)>1,"DUPLICATE","") | Z20: =IF(AND(Y20="",COUNTIFS($C$6:C20,C20,$Q$6:Q20,Q20,$D$6:D20,">="&(D20-14),$D$6:D20,"<="&(D20+14))>1),"CHECK","") | AA20: =IF(ABS(O20-P20)>0.01,"TAX?","") -> TAX? | AB20: =IF(R20<>"Y","NO DOCS","") | AC20: =IF(AND(U20="Paid",S20<>"Approved"),"CONTROL","") | AD20: =IF(OR(D20>$D$3,F20<D20),"DATE?","") | AE20: =SUMPRODUCT(--(LEN(Y20:AD20)>0)) -> 1 | AF20: =IF(AND(X20>0,F20<$D$3),$D$3-F20,0) -> 0 | AG20: =IF(AF20>0,AF20+ROW()/10000,"")
A21: AP-0016 | B21: PF-88277 | C21: Prairie Fuel & Lube Inc. | D21: 46252 | E21: =INDEX(Lists!$B$5:$B$13,MATCH(C21,Lists!$A$5:$A$13,0)) -> 15 | F21: =D21+E21 -> 46267 | G21: PO-4458 | H21: Diesel and hydraulic oil | I21: Fuel & Lubricants | J21: =INDEX(Lists!$E$5:$E$14,MATCH(I21,Lists!$D$5:$D$14,0)) -> 5400 | K21: =INDEX(Lists!$F$5:$F$14,MATCH(I21,Lists!$D$5:$D$14,0)) -> Y | L21: J-102 | M21: 2860 | N21: GST5 | O21: 143 | P21: =ROUND(M21*INDEX(Lists!$I$5:$I$6,MATCH(N21,Lists!$H$5:$H$6,0)),2) -> 143 | Q21: =M21+O21 -> 3003 | R21: Y | S21: Pending | T21: R. Singh | U21: Paid | V21: 46267 | W21: 3003 | X21: =IF(S21="Rejected",0,Q21-W21) -> 0 | Y21: =IF(COUNTIFS($C$6:C21,C21,$B$6:B21,B21)>1,"DUPLICATE","") | Z21: =IF(AND(Y21="",COUNTIFS($C$6:C21,C21,$Q$6:Q21,Q21,$D$6:D21,">="&(D21-14),$D$6:D21,"<="&(D21+14))>1),"CHECK","") | AA21: =IF(ABS(O21-P21)>0.01,"TAX?","") | AB21: =IF(R21<>"Y","NO DOCS","") | AC21: =IF(AND(U21="Paid",S21<>"Approved"),"CONTROL","") -> CONTROL | AD21: =IF(OR(D21>$D$3,F21<D21),"DATE?","") | AE21: =SUMPRODUCT(--(LEN(Y21:AD21)>0)) -> 1 | AF21: =IF(AND(X21>0,F21<$D$3),$D$3-F21,0) -> 0 | AG21: =IF(AF21>0,AF21+ROW()/10000,"")
A22: AP-0017 | B22: BV-5601 | C22: Bow Valley Office Products Ltd. | D22: 46254 | E22: =INDEX(Lists!$B$5:$B$13,MATCH(C22,Lists!$A$5:$A$13,0)) -> 30 | F22: =D22+E22 -> 46284 | G22: PO-4461 | H22: Binders, safety signage | I22: Office Supplies | J22: =INDEX(Lists!$E$5:$E$14,MATCH(I22,Lists!$D$5:$D$14,0)) -> 6200 | K22: =INDEX(Lists!$F$5:$F$14,MATCH(I22,Lists!$D$5:$D$14,0)) -> N | M22: 274.9 | N22: GST5 | O22: 13.75 | P22: =ROUND(M22*INDEX(Lists!$I$5:$I$6,MATCH(N22,Lists!$H$5:$H$6,0)),2) -> 13.75 | Q22: =M22+O22 -> 288.65 | R22: Y | S22: Approved | T22: J. Nguyen | U22: Paid | V22: 46283 | W22: 288.65 | X22: =IF(S22="Rejected",0,Q22-W22) -> 0 | Y22: =IF(COUNTIFS($C$6:C22,C22,$B$6:B22,B22)>1,"DUPLICATE","") | Z22: =IF(AND(Y22="",COUNTIFS($C$6:C22,C22,$Q$6:Q22,Q22,$D$6:D22,">="&(D22-14),$D$6:D22,"<="&(D22+14))>1),"CHECK","") | AA22: =IF(ABS(O22-P22)>0.01,"TAX?","") | AB22: =IF(R22<>"Y","NO DOCS","") | AC22: =IF(AND(U22="Paid",S22<>"Approved"),"CONTROL","") | AD22: =IF(OR(D22>$D$3,F22<D22),"DATE?","") | AE22: =SUMPRODUCT(--(LEN(Y22:AD22)>0)) -> 0 | AF22: =IF(AND(X22>0,F22<$D$3),$D$3-F22,0) -> 0 | AG22: =IF(AF22>0,AF22+ROW()/10000,"")
A23: AP-0018 | B23: PMI-2026-Q3 | C23: Pinnacle Mutual Insurance Co. | D23: 46253 | E23: =INDEX(Lists!$B$5:$B$13,MATCH(C23,Lists!$A$5:$A$13,0)) -> 30 | F23: =D23+E23 -> 46283 | G23: PO-4390 | H23: Commercial liability premium, Q3 | I23: Insurance | J23: =INDEX(Lists!$E$5:$E$14,MATCH(I23,Lists!$D$5:$D$14,0)) -> 6600 | K23: =INDEX(Lists!$F$5:$F$14,MATCH(I23,Lists!$D$5:$D$14,0)) -> N | M23: 6200 | N23: EXEMPT | O23: 310 | P23: =ROUND(M23*INDEX(Lists!$I$5:$I$6,MATCH(N23,Lists!$H$5:$H$6,0)),2) -> 0 | Q23: =M23+O23 -> 6510 | R23: Y | S23: Approved | T23: A. Carter | U23: Paid | V23: 46281 | W23: 6510 | X23: =IF(S23="Rejected",0,Q23-W23) -> 0 | Y23: =IF(COUNTIFS($C$6:C23,C23,$B$6:B23,B23)>1,"DUPLICATE","") | Z23: =IF(AND(Y23="",COUNTIFS($C$6:C23,C23,$Q$6:Q23,Q23,$D$6:D23,">="&(D23-14),$D$6:D23,"<="&(D23+14))>1),"CHECK","") | AA23: =IF(ABS(O23-P23)>0.01,"TAX?","") -> TAX? | AB23: =IF(R23<>"Y","NO DOCS","") | AC23: =IF(AND(U23="Paid",S23<>"Approved"),"CONTROL","") | AD23: =IF(OR(D23>$D$3,F23<D23),"DATE?","") | AE23: =SUMPRODUCT(--(LEN(Y23:AD23)>0)) -> 1 | AF23: =IF(AND(X23>0,F23<$D$3),$D$3-F23,0) -> 0 | AG23: =IF(AF23>0,AF23+ROW()/10000,"")
A24: AP-0019 | B24: NG-7752 | C24: Northgate IT Services Inc. | D24: 46254 | E24: =INDEX(Lists!$B$5:$B$13,MATCH(C24,Lists!$A$5:$A$13,0)) -> 30 | F24: =D24+E24 -> 46284 | G24: PO-4465 | H24: Cloud backup, September | I24: IT & Software | J24: =INDEX(Lists!$E$5:$E$14,MATCH(I24,Lists!$D$5:$D$14,0)) -> 6300 | K24: =INDEX(Lists!$F$5:$F$14,MATCH(I24,Lists!$D$5:$D$14,0)) -> N | M24: 1325 | N24: GST5 | O24: 66.25 | P24: =ROUND(M24*INDEX(Lists!$I$5:$I$6,MATCH(N24,Lists!$H$5:$H$6,0)),2) -> 66.25 | Q24: =M24+O24 -> 1391.25 | R24: Y | S24: Approved | T24: R. Singh | U24: Partially Paid | V24: 46285 | W24: 700 | X24: =IF(S24="Rejected",0,Q24-W24) -> 691.25 | Y24: =IF(COUNTIFS($C$6:C24,C24,$B$6:B24,B24)>1,"DUPLICATE","") | Z24: =IF(AND(Y24="",COUNTIFS($C$6:C24,C24,$Q$6:Q24,Q24,$D$6:D24,">="&(D24-14),$D$6:D24,"<="&(D24+14))>1),"CHECK","") | AA24: =IF(ABS(O24-P24)>0.01,"TAX?","") | AB24: =IF(R24<>"Y","NO DOCS","") | AC24: =IF(AND(U24="Paid",S24<>"Approved"),"CONTROL","") | AD24: =IF(OR(D24>$D$3,F24<D24),"DATE?","") | AE24: =SUMPRODUCT(--(LEN(Y24:AD24)>0)) -> 0 | AF24: =IF(AND(X24>0,F24<$D$3),$D$3-F24,0) -> 20 | AG24: =IF(AF24>0,AF24+ROW()/10000,"") -> 20.0024
A25: AP-0020 | B25: RSS-20431A | C25: Ridgeline Safety Supply Ltd. | D25: 46231 | E25: =INDEX(Lists!$B$5:$B$13,MATCH(C25,Lists!$A$5:$A$13,0)) -> 30 | F25: =D25+E25 -> 46261 | G25: PO-4430 | H25: Fall arrest harnesses (6) | I25: Safety Supplies | J25: =INDEX(Lists!$E$5:$E$14,MATCH(I25,Lists!$D$5:$D$14,0)) -> 6100 | K25: =INDEX(Lists!$F$5:$F$14,MATCH(I25,Lists!$D$5:$D$14,0)) -> N | M25: 2175 | N25: GST5 | O25: 108.75 | P25: =ROUND(M25*INDEX(Lists!$I$5:$I$6,MATCH(N25,Lists!$H$5:$H$6,0)),2) -> 108.75 | Q25: =M25+O25 -> 2283.75 | R25: Y | S25: Pending | T25: J. Nguyen | U25: Unpaid | W25: 0 | X25: =IF(S25="Rejected",0,Q25-W25) -> 2283.75 | Y25: =IF(COUNTIFS($C$6:C25,C25,$B$6:B25,B25)>1,"DUPLICATE","") | Z25: =IF(AND(Y25="",COUNTIFS($C$6:C25,C25,$Q$6:Q25,Q25,$D$6:D25,">="&(D25-14),$D$6:D25,"<="&(D25+14))>1),"CHECK","") -> CHECK | AA25: =IF(ABS(O25-P25)>0.01,"TAX?","") | AB25: =IF(R25<>"Y","NO DOCS","") | AC25: =IF(AND(U25="Paid",S25<>"Approved"),"CONTROL","") | AD25: =IF(OR(D25>$D$3,F25<D25),"DATE?","") | AE25: =SUMPRODUCT(--(LEN(Y25:AD25)>0)) -> 1 | AF25: =IF(AND(X25>0,F25<$D$3),$D$3-F25,0) -> 43 | AG25: =IF(AF25>0,AF25+ROW()/10000,"") -> 43.0025
A26: AP-0021 | B26: SCF-1241 | C26: Summit Courier & Freight Ltd. | D26: 46275 | E26: =INDEX(Lists!$B$5:$B$13,MATCH(C26,Lists!$A$5:$A$13,0)) -> 15 | F26: =D26+E26 -> 46290 | G26: PO-4474 | H26: Freight, fabricated spools | I26: Courier & Freight | J26: =INDEX(Lists!$E$5:$E$14,MATCH(I26,Lists!$D$5:$D$14,0)) -> 6400 | K26: =INDEX(Lists!$F$5:$F$14,MATCH(I26,Lists!$D$5:$D$14,0)) -> N | L26: J-102 | M26: 918 | N26: GST5 | O26: 45.9 | P26: =ROUND(M26*INDEX(Lists!$I$5:$I$6,MATCH(N26,Lists!$H$5:$H$6,0)),2) -> 45.9 | Q26: =M26+O26 -> 963.9 | R26: Y | S26: Approved | T26: R. Singh | U26: Unpaid | W26: 0 | X26: =IF(S26="Rejected",0,Q26-W26) -> 963.9 | Y26: =IF(COUNTIFS($C$6:C26,C26,$B$6:B26,B26)>1,"DUPLICATE","") | Z26: =IF(AND(Y26="",COUNTIFS($C$6:C26,C26,$Q$6:Q26,Q26,$D$6:D26,">="&(D26-14),$D$6:D26,"<="&(D26+14))>1),"CHECK","") | AA26: =IF(ABS(O26-P26)>0.01,"TAX?","") | AB26: =IF(R26<>"Y","NO DOCS","") | AC26: =IF(AND(U26="Paid",S26<>"Approved"),"CONTROL","") | AD26: =IF(OR(D26>$D$3,F26<D26),"DATE?","") | AE26: =SUMPRODUCT(--(LEN(Y26:AD26)>0)) -> 0 | AF26: =IF(AND(X26>0,F26<$D$3),$D$3-F26,0) -> 14 | AG26: =IF(AF26>0,AF26+ROW()/10000,"") -> 14.0026
A27: AP-0022 | B27: BV-5640 | C27: Bow Valley Office Products Ltd. | D27: 46289 | E27: =INDEX(Lists!$B$5:$B$13,MATCH(C27,Lists!$A$5:$A$13,0)) -> 30 | F27: =D27+E27 -> 46319 | G27: PO-4480 | H27: Ergonomic chairs (4) | I27: Office Supplies | J27: =INDEX(Lists!$E$5:$E$14,MATCH(I27,Lists!$D$5:$D$14,0)) -> 6200 | K27: =INDEX(Lists!$F$5:$F$14,MATCH(I27,Lists!$D$5:$D$14,0)) -> N | M27: 1480 | N27: GST5 | O27: 74 | P27: =ROUND(M27*INDEX(Lists!$I$5:$I$6,MATCH(N27,Lists!$H$5:$H$6,0)),2) -> 74 | Q27: =M27+O27 -> 1554 | R27: Y | S27: Approved | T27: J. Nguyen | U27: Scheduled | V27: 46318 | W27: 0 | X27: =IF(S27="Rejected",0,Q27-W27) -> 1554 | Y27: =IF(COUNTIFS($C$6:C27,C27,$B$6:B27,B27)>1,"DUPLICATE","") | Z27: =IF(AND(Y27="",COUNTIFS($C$6:C27,C27,$Q$6:Q27,Q27,$D$6:D27,">="&(D27-14),$D$6:D27,"<="&(D27+14))>1),"CHECK","") | AA27: =IF(ABS(O27-P27)>0.01,"TAX?","") | AB27: =IF(R27<>"Y","NO DOCS","") | AC27: =IF(AND(U27="Paid",S27<>"Approved"),"CONTROL","") | AD27: =IF(OR(D27>$D$3,F27<D27),"DATE?","") | AE27: =SUMPRODUCT(--(LEN(Y27:AD27)>0)) -> 0 | AF27: =IF(AND(X27>0,F27<$D$3),$D$3-F27,0) -> 0 | AG27: =IF(AF27>0,AF27+ROW()/10000,"")
A28: AP-0023 | B28: CCF-0951 | C28: Cinder Creek Fabrication Ltd. | D28: 46267 | E28: =INDEX(Lists!$B$5:$B$13,MATCH(C28,Lists!$A$5:$A$13,0)) -> 30 | F28: =D28+E28 -> 46297 | G28: PO-4468 | H28: Pipe supports, 40 units | I28: Job Materials | J28: =INDEX(Lists!$E$5:$E$14,MATCH(I28,Lists!$D$5:$D$14,0)) -> 5100 | K28: =INDEX(Lists!$F$5:$F$14,MATCH(I28,Lists!$D$5:$D$14,0)) -> Y | L28: J-101 | M28: 6750 | N28: GST5 | O28: 337.5 | P28: =ROUND(M28*INDEX(Lists!$I$5:$I$6,MATCH(N28,Lists!$H$5:$H$6,0)),2) -> 337.5 | Q28: =M28+O28 -> 7087.5 | R28: Y | S28: Approved | T28: A. Carter | U28: Paid | V28: 46296 | W28: 7087.5 | X28: =IF(S28="Rejected",0,Q28-W28) -> 0 | Y28: =IF(COUNTIFS($C$6:C28,C28,$B$6:B28,B28)>1,"DUPLICATE","") | Z28: =IF(AND(Y28="",COUNTIFS($C$6:C28,C28,$Q$6:Q28,Q28,$D$6:D28,">="&(D28-14),$D$6:D28,"<="&(D28+14))>1),"CHECK","") | AA28: =IF(ABS(O28-P28)>0.01,"TAX?","") | AB28: =IF(R28<>"Y","NO DOCS","") | AC28: =IF(AND(U28="Paid",S28<>"Approved"),"CONTROL","") | AD28: =IF(OR(D28>$D$3,F28<D28),"DATE?","") | AE28: =SUMPRODUCT(--(LEN(Y28:AD28)>0)) -> 0 | AF28: =IF(AND(X28>0,F28<$D$3),$D$3-F28,0) -> 0 | AG28: =IF(AF28>0,AF28+ROW()/10000,"")
A29: AP-0024 | B29: PF-88391 | C29: Prairie Fuel & Lube Inc. | D29: 46267 | E29: =INDEX(Lists!$B$5:$B$13,MATCH(C29,Lists!$A$5:$A$13,0)) -> 15 | F29: =D29+E29 -> 46282 | G29: PO-4471 | H29: Diesel, site generators | I29: Fuel & Lubricants | J29: =INDEX(Lists!$E$5:$E$14,MATCH(I29,Lists!$D$5:$D$14,0)) -> 5400 | K29: =INDEX(Lists!$F$5:$F$14,MATCH(I29,Lists!$D$5:$D$14,0)) -> Y | L29: J-103 | M29: 3120 | N29: GST5 | O29: 156 | P29: =ROUND(M29*INDEX(Lists!$I$5:$I$6,MATCH(N29,Lists!$H$5:$H$6,0)),2) -> 156 | Q29: =M29+O29 -> 3276 | R29: N | S29: Approved | T29: R. Singh | U29: Unpaid | W29: 0 | X29: =IF(S29="Rejected",0,Q29-W29) -> 3276 | Y29: =IF(COUNTIFS($C$6:C29,C29,$B$6:B29,B29)>1,"DUPLICATE","") | Z29: =IF(AND(Y29="",COUNTIFS($C$6:C29,C29,$Q$6:Q29,Q29,$D$6:D29,">="&(D29-14),$D$6:D29,"<="&(D29+14))>1),"CHECK","") | AA29: =IF(ABS(O29-P29)>0.01,"TAX?","") | AB29: =IF(R29<>"Y","NO DOCS","") -> NO DOCS | AC29: =IF(AND(U29="Paid",S29<>"Approved"),"CONTROL","") | AD29: =IF(OR(D29>$D$3,F29<D29),"DATE?","") | AE29: =SUMPRODUCT(--(LEN(Y29:AD29)>0)) -> 1 | AF29: =IF(AND(X29>0,F29<$D$3),$D$3-F29,0) -> 22 | AG29: =IF(AF29>0,AF29+ROW()/10000,"") -> 22.0029
A30: AP-0025 | B30: PF-88455 | C30: Prairie Fuel & Lube Inc. | D30: 46297 | E30: =INDEX(Lists!$B$5:$B$13,MATCH(C30,Lists!$A$5:$A$13,0)) -> 15 | F30: =D30+E30 -> 46312 | G30: PO-4486 | H30: Diesel, site generators | I30: Fuel & Lubricants | J30: =INDEX(Lists!$E$5:$E$14,MATCH(I30,Lists!$D$5:$D$14,0)) -> 5400 | K30: =INDEX(Lists!$F$5:$F$14,MATCH(I30,Lists!$D$5:$D$14,0)) -> Y | L30: J-101 | M30: 2980 | N30: GST5 | O30: 149 | P30: =ROUND(M30*INDEX(Lists!$I$5:$I$6,MATCH(N30,Lists!$H$5:$H$6,0)),2) -> 149 | Q30: =M30+O30 -> 3129 | R30: Y | S30: Approved | T30: R. Singh | U30: Scheduled | V30: 46311 | W30: 0 | X30: =IF(S30="Rejected",0,Q30-W30) -> 3129 | Y30: =IF(COUNTIFS($C$6:C30,C30,$B$6:B30,B30)>1,"DUPLICATE","") | Z30: =IF(AND(Y30="",COUNTIFS($C$6:C30,C30,$Q$6:Q30,Q30,$D$6:D30,">="&(D30-14),$D$6:D30,"<="&(D30+14))>1),"CHECK","") | AA30: =IF(ABS(O30-P30)>0.01,"TAX?","") | AB30: =IF(R30<>"Y","NO DOCS","") | AC30: =IF(AND(U30="Paid",S30<>"Approved"),"CONTROL","") | AD30: =IF(OR(D30>$D$3,F30<D30),"DATE?","") | AE30: =SUMPRODUCT(--(LEN(Y30:AD30)>0)) -> 0 | AF30: =IF(AND(X30>0,F30<$D$3),$D$3-F30,0) -> 0 | AG30: =IF(AF30>0,AF30+ROW()/10000,"")
A31: AP-0026 | B31: NG-7801 | C31: Northgate IT Services Inc. | D31: 46300 | E31: =INDEX(Lists!$B$5:$B$13,MATCH(C31,Lists!$A$5:$A$13,0)) -> 30 | F31: =D31+E31 -> 46330 | G31: PO-4490 | H31: Cloud backup, October | I31: IT & Software | J31: =INDEX(Lists!$E$5:$E$14,MATCH(I31,Lists!$D$5:$D$14,0)) -> 6300 | K31: =INDEX(Lists!$F$5:$F$14,MATCH(I31,Lists!$D$5:$D$14,0)) -> N | M31: 1325 | N31: GST5 | O31: 66.25 | P31: =ROUND(M31*INDEX(Lists!$I$5:$I$6,MATCH(N31,Lists!$H$5:$H$6,0)),2) -> 66.25 | Q31: =M31+O31 -> 1391.25 | R31: Y | S31: Pending | T31: R. Singh | U31: Unpaid | W31: 0 | X31: =IF(S31="Rejected",0,Q31-W31) -> 1391.25 | Y31: =IF(COUNTIFS($C$6:C31,C31,$B$6:B31,B31)>1,"DUPLICATE","") | Z31: =IF(AND(Y31="",COUNTIFS($C$6:C31,C31,$Q$6:Q31,Q31,$D$6:D31,">="&(D31-14),$D$6:D31,"<="&(D31+14))>1),"CHECK","") | AA31: =IF(ABS(O31-P31)>0.01,"TAX?","") | AB31: =IF(R31<>"Y","NO DOCS","") | AC31: =IF(AND(U31="Paid",S31<>"Approved"),"CONTROL","") | AD31: =IF(OR(D31>$D$3,F31<D31),"DATE?","") | AE31: =SUMPRODUCT(--(LEN(Y31:AD31)>0)) -> 0 | AF31: =IF(AND(X31>0,F31<$D$3),$D$3-F31,0) -> 0 | AG31: =IF(AF31>0,AF31+ROW()/10000,"")
A32: AP-0027 | B32: FER-3388 | C32: Foothills Equipment Rentals Ltd. | D32: 46301 | E32: =INDEX(Lists!$B$5:$B$13,MATCH(C32,Lists!$A$5:$A$13,0)) -> 45 | F32: =D32+E32 -> 46346 | G32: PO-4492 | H32: Crane rental, 5 days | I32: Equipment Rental (Job) | J32: =INDEX(Lists!$E$5:$E$14,MATCH(I32,Lists!$D$5:$D$14,0)) -> 5300 | K32: =INDEX(Lists!$F$5:$F$14,MATCH(I32,Lists!$D$5:$D$14,0)) -> Y | L32: J-103 | M32: 12400 | N32: GST5 | O32: 620 | P32: =ROUND(M32*INDEX(Lists!$I$5:$I$6,MATCH(N32,Lists!$H$5:$H$6,0)),2) -> 620 | Q32: =M32+O32 -> 13020 | R32: Y | S32: Pending | T32: A. Carter | U32: Unpaid | W32: 0 | X32: =IF(S32="Rejected",0,Q32-W32) -> 13020 | Y32: =IF(COUNTIFS($C$6:C32,C32,$B$6:B32,B32)>1,"DUPLICATE","") | Z32: =IF(AND(Y32="",COUNTIFS($C$6:C32,C32,$Q$6:Q32,Q32,$D$6:D32,">="&(D32-14),$D$6:D32,"<="&(D32+14))>1),"CHECK","") | AA32: =IF(ABS(O32-P32)>0.01,"TAX?","") | AB32: =IF(R32<>"Y","NO DOCS","") | AC32: =IF(AND(U32="Paid",S32<>"Approved"),"CONTROL","") | AD32: =IF(OR(D32>$D$3,F32<D32),"DATE?","") | AE32: =SUMPRODUCT(--(LEN(Y32:AD32)>0)) -> 0 | AF32: =IF(AND(X32>0,F32<$D$3),$D$3-F32,0) -> 0 | AG32: =IF(AF32>0,AF32+ROW()/10000,"")
A33: AP-0028 | B33: PMI-2026-Q4 | C33: Pinnacle Mutual Insurance Co. | D33: 46309 | E33: =INDEX(Lists!$B$5:$B$13,MATCH(C33,Lists!$A$5:$A$13,0)) -> 30 | F33: =D33+E33 -> 46339 | G33: PO-4495 | H33: Commercial liability premium, Q4 | I33: Insurance | J33: =INDEX(Lists!$E$5:$E$14,MATCH(I33,Lists!$D$5:$D$14,0)) -> 6600 | K33: =INDEX(Lists!$F$5:$F$14,MATCH(I33,Lists!$D$5:$D$14,0)) -> N | M33: 6200 | N33: EXEMPT | O33: 0 | P33: =ROUND(M33*INDEX(Lists!$I$5:$I$6,MATCH(N33,Lists!$H$5:$H$6,0)),2) -> 0 | Q33: =M33+O33 -> 6200 | R33: Y | S33: Pending | T33: A. Carter | U33: Unpaid | W33: 0 | X33: =IF(S33="Rejected",0,Q33-W33) -> 6200 | Y33: =IF(COUNTIFS($C$6:C33,C33,$B$6:B33,B33)>1,"DUPLICATE","") | Z33: =IF(AND(Y33="",COUNTIFS($C$6:C33,C33,$Q$6:Q33,Q33,$D$6:D33,">="&(D33-14),$D$6:D33,"<="&(D33+14))>1),"CHECK","") | AA33: =IF(ABS(O33-P33)>0.01,"TAX?","") | AB33: =IF(R33<>"Y","NO DOCS","") | AC33: =IF(AND(U33="Paid",S33<>"Approved"),"CONTROL","") | AD33: =IF(OR(D33>$D$3,F33<D33),"DATE?","") -> DATE? | AE33: =SUMPRODUCT(--(LEN(Y33:AD33)>0)) -> 1 | AF33: =IF(AND(X33>0,F33<$D$3),$D$3-F33,0) -> 0 | AG33: =IF(AF33>0,AF33+ROW()/10000,"")
A34: Totals | M34: =SUM(M6:M33) -> 112629.3 | O34: =SUM(O6:O33) -> 5341.48 | P34: =SUM(P6:P33) -> 5011.48 | Q34: =SUM(Q6:Q33) -> 117970.78 | W34: =SUM(W6:W33) -> 29536 | X34: =SUM(X6:X33) -> 85914.78 | AE34: =SUM(AE6:AE33) -> 8

Sheet Overdue_Report
A1: SELF-DIRECTED PRACTICE PROJECT. All suppliers, invoices, amounts, employees and approvers are fictional and created for skills practice. This is not professional accounts payable experience.
A2: Overdue Payables Report
A3: Aging of unpaid supplier invoices. Every figure is a formula on AP_Register.
A4: As-of date | B4: =AP_Register!D3 -> 46304
A5: Total outstanding ($) | B5: Overdue balance ($) | C5: Overdue as % of outstanding | D5: Overdue invoices (#) | E5: Oldest overdue (days)
A6: =SUM(AP_Register!$X$6:$X$33) -> 85914.78 | B6: =SUMIFS(AP_Register!$X$6:$X$33,AP_Register!$AF$6:$AF$33,">0") -> 60620.53 | C6: =IFERROR(B6/A6,0) -> 0.70558907 | D6: =COUNTIFS(AP_Register!$AF$6:$AF$33,">0") -> 11 | E6: =MAX(AP_Register!$AF$6:$AF$33) -> 93
A8: Aging of outstanding balances
A9: Bucket | B9: # invoices | C9: Balance ($) | D9: % of outstanding
A10: Not yet due | B10: =COUNTIFS(AP_Register!$X$6:$X$33,">0",AP_Register!$AF$6:$AF$33,0) -> 5 | C10: =SUMIFS(AP_Register!$X$6:$X$33,AP_Register!$X$6:$X$33,">0",AP_Register!$AF$6:$AF$33,0) -> 25294.25 | D10: =IFERROR(C10/$C$15,0) -> 0.29441093
A11: 1 to 30 days overdue | B11: =COUNTIFS(AP_Register!$AF$6:$AF$33,">=1",AP_Register!$AF$6:$AF$33,"<=30") -> 4 | C11: =SUMIFS(AP_Register!$X$6:$X$33,AP_Register!$AF$6:$AF$33,">=1",AP_Register!$AF$6:$AF$33,"<=30") -> 9782.15 | D11: =IFERROR(C11/$C$15,0) -> 0.11385876
A12: 31 to 60 days overdue | B12: =COUNTIFS(AP_Register!$AF$6:$AF$33,">=31",AP_Register!$AF$6:$AF$33,"<=60") -> 5 | C12: =SUMIFS(AP_Register!$X$6:$X$33,AP_Register!$AF$6:$AF$33,">=31",AP_Register!$AF$6:$AF$33,"<=60") -> 25585.88 | D12: =IFERROR(C12/$C$15,0) -> 0.29780534
A13: 61 to 90 days overdue | B13: =COUNTIFS(AP_Register!$AF$6:$AF$33,">=61",AP_Register!$AF$6:$AF$33,"<=90") -> 1 | C13: =SUMIFS(AP_Register!$X$6:$X$33,AP_Register!$AF$6:$AF$33,">=61",AP_Register!$AF$6:$AF$33,"<=90") -> 10290 | D13: =IFERROR(C13/$C$15,0) -> 0.11976985
A14: Over 90 days overdue | B14: =COUNTIFS(AP_Register!$AF$6:$AF$33,">90") -> 1 | C14: =SUMIFS(AP_Register!$X$6:$X$33,AP_Register!$AF$6:$AF$33,">90") -> 14962.5 | D14: =IFERROR(C14/$C$15,0) -> 0.17415513
A15: Total | B15: =SUM(B10:B14) -> 16 | C15: =SUM(C10:C14) -> 85914.78 | D15: =SUM(D10:D14) -> 1
A16: Check: buckets = register balance | C16: =IF(ABS(C15-A6)<0.005,"OK","DIFFERENCE") -> OK
A18: Overdue by supplier
A19: Supplier | B19: Overdue invoices | C19: Overdue balance ($) | D19: Total outstanding ($)
A20: =Lists!A5 -> Ridgeline Safety Supply Ltd. | B20: =COUNTIFS(AP_Register!$C$6:$C$33,A20,AP_Register!$AF$6:$AF$33,">0") -> 2 | C20: =SUMIFS(AP_Register!$X$6:$X$33,AP_Register!$C$6:$C$33,A20,AP_Register!$AF$6:$AF$33,">0") -> 7134.75 | D20: =SUMIFS(AP_Register!$X$6:$X$33,AP_Register!$C$6:$C$33,A20) -> 7134.75
A21: =Lists!A6 -> Bow Valley Office Products Ltd. | B21: =COUNTIFS(AP_Register!$C$6:$C$33,A21,AP_Register!$AF$6:$AF$33,">0") -> 0 | C21: =SUMIFS(AP_Register!$X$6:$X$33,AP_Register!$C$6:$C$33,A21,AP_Register!$AF$6:$AF$33,">0") -> 0 | D21: =SUMIFS(AP_Register!$X$6:$X$33,AP_Register!$C$6:$C$33,A21) -> 1554
A22: =Lists!A7 -> Prairie Fuel & Lube Inc. | B22: =COUNTIFS(AP_Register!$C$6:$C$33,A22,AP_Register!$AF$6:$AF$33,">0") -> 1 | C22: =SUMIFS(AP_Register!$X$6:$X$33,AP_Register!$C$6:$C$33,A22,AP_Register!$AF$6:$AF$33,">0") -> 3276 | D22: =SUMIFS(AP_Register!$X$6:$X$33,AP_Register!$C$6:$C$33,A22) -> 6405
A23: =Lists!A8 -> Foothills Equipment Rentals Ltd. | B23: =COUNTIFS(AP_Register!$C$6:$C$33,A23,AP_Register!$AF$6:$AF$33,">0") -> 1 | C23: =SUMIFS(AP_Register!$X$6:$X$33,AP_Register!$C$6:$C$33,A23,AP_Register!$AF$6:$AF$33,">0") -> 8820 | D23: =SUMIFS(AP_Register!$X$6:$X$33,AP_Register!$C$6:$C$33,A23) -> 21840
A24: =Lists!A9 -> Cinder Creek Fabrication Ltd. | B24: =COUNTIFS(AP_Register!$C$6:$C$33,A24,AP_Register!$AF$6:$AF$33,">0") -> 3 | C24: =SUMIFS(AP_Register!$X$6:$X$33,AP_Register!$C$6:$C$33,A24,AP_Register!$AF$6:$AF$33,">0") -> 37117.5 | D24: =SUMIFS(AP_Register!$X$6:$X$33,AP_Register!$C$6:$C$33,A24) -> 37117.5
A25: =Lists!A10 -> Northgate IT Services Inc. | B25: =COUNTIFS(AP_Register!$C$6:$C$33,A25,AP_Register!$AF$6:$AF$33,">0") -> 1 | C25: =SUMIFS(AP_Register!$X$6:$X$33,AP_Register!$C$6:$C$33,A25,AP_Register!$AF$6:$AF$33,">0") -> 691.25 | D25: =SUMIFS(AP_Register!$X$6:$X$33,AP_Register!$C$6:$C$33,A25) -> 2082.5
A26: =Lists!A11 -> Summit Courier & Freight Ltd. | B26: =COUNTIFS(AP_Register!$C$6:$C$33,A26,AP_Register!$AF$6:$AF$33,">0") -> 2 | C26: =SUMIFS(AP_Register!$X$6:$X$33,AP_Register!$C$6:$C$33,A26,AP_Register!$AF$6:$AF$33,">0") -> 1638.53 | D26: =SUMIFS(AP_Register!$X$6:$X$33,AP_Register!$C$6:$C$33,A26) -> 1638.53
A27: =Lists!A12 -> Clearwater Janitorial Ltd. | B27: =COUNTIFS(AP_Register!$C$6:$C$33,A27,AP_Register!$AF$6:$AF$33,">0") -> 1 | C27: =SUMIFS(AP_Register!$X$6:$X$33,AP_Register!$C$6:$C$33,A27,AP_Register!$AF$6:$AF$33,">0") -> 1942.5 | D27: =SUMIFS(AP_Register!$X$6:$X$33,AP_Register!$C$6:$C$33,A27) -> 1942.5
A28: =Lists!A13 -> Pinnacle Mutual Insurance Co. | B28: =COUNTIFS(AP_Register!$C$6:$C$33,A28,AP_Register!$AF$6:$AF$33,">0") -> 0 | C28: =SUMIFS(AP_Register!$X$6:$X$33,AP_Register!$C$6:$C$33,A28,AP_Register!$AF$6:$AF$33,">0") -> 0 | D28: =SUMIFS(AP_Register!$X$6:$X$33,AP_Register!$C$6:$C$33,A28) -> 6200
A29: Total | B29: =SUM(B20:B28) -> 11 | C29: =SUM(C20:C28) -> 60620.53 | D29: =SUM(D20:D28) -> 85914.78
A31: Overdue invoices, oldest first (action list)
A32: Rank | B32: AP # | C32: Supplier | D32: Invoice no. | E32: Due date | F32: Days overdue | G32: Balance ($) | H32: Approval | I32: Payment status | J32: Suggested next step | K32: (row)
A33: =IF(K33="","",1) -> 1 | B33: =IF($K33="","",INDEX(AP_Register!$A$6:$A$33,$K33)) -> AP-0001 | C33: =IF($K33="","",INDEX(AP_Register!$C$6:$C$33,$K33)) -> Cinder Creek Fabrication Ltd. | D33: =IF($K33="","",INDEX(AP_Register!$B$6:$B$33,$K33)) -> CCF-0871 | E33: =IF($K33="","",INDEX(AP_Register!$F$6:$F$33,$K33)) -> 46211 | F33: =IF($K33="","",INDEX(AP_Register!$AF$6:$AF$33,$K33)) -> 93 | G33: =IF($K33="","",INDEX(AP_Register!$X$6:$X$33,$K33)) -> 14962.5 | H33: =IF($K33="","",INDEX(AP_Register!$S$6:$S$33,$K33)) -> On Hold | I33: =IF($K33="","",INDEX(AP_Register!$U$6:$U$33,$K33)) -> Unpaid | J33: =IF($K33="","",IF(H33="On Hold","Resolve dispute with supplier",IF(H33="Pending","Chase approver",IF(H33="Rejected","Confirm with supplier",IF(INDEX(AP_Register!$AB$6:$AB$33,$K33)<>"","Obtain supporting docs, then pay",IF(INDEX(AP_Register!$AE$6:$AE$33,$K33)>0,"Clear exceptions, then pay","Schedule payment in next run")))))) -> Resolve dispute with supplier | K33: =IFERROR(MATCH(LARGE(AP_Register!$AG$6:$AG$33,1),AP_Register!$AG$6:$AG$33,0),"") -> 1
A34: =IF(K34="","",2) -> 2 | B34: =IF($K34="","",INDEX(AP_Register!$A$6:$A$33,$K34)) -> AP-0006 | C34: =IF($K34="","",INDEX(AP_Register!$C$6:$C$33,$K34)) -> Cinder Creek Fabrication Ltd. | D34: =IF($K34="","",INDEX(AP_Register!$B$6:$B$33,$K34)) -> CCF-0902 | E34: =IF($K34="","",INDEX(AP_Register!$F$6:$F$33,$K34)) -> 46243 | F34: =IF($K34="","",INDEX(AP_Register!$AF$6:$AF$33,$K34)) -> 61 | G34: =IF($K34="","",INDEX(AP_Register!$X$6:$X$33,$K34)) -> 10290 | H34: =IF($K34="","",INDEX(AP_Register!$S$6:$S$33,$K34)) -> On Hold | I34: =IF($K34="","",INDEX(AP_Register!$U$6:$U$33,$K34)) -> Unpaid | J34: =IF($K34="","",IF(H34="On Hold","Resolve dispute with supplier",IF(H34="Pending","Chase approver",IF(H34="Rejected","Confirm with supplier",IF(INDEX(AP_Register!$AB$6:$AB$33,$K34)<>"","Obtain supporting docs, then pay",IF(INDEX(AP_Register!$AE$6:$AE$33,$K34)>0,"Clear exceptions, then pay","Schedule payment in next run")))))) -> Resolve dispute with supplier | K34: =IFERROR(MATCH(LARGE(AP_Register!$AG$6:$AG$33,2),AP_Register!$AG$6:$AG$33,0),"") -> 6
A35: =IF(K35="","",3) -> 3 | B35: =IF($K35="","",INDEX(AP_Register!$A$6:$A$33,$K35)) -> AP-0010 | C35: =IF($K35="","",INDEX(AP_Register!$C$6:$C$33,$K35)) -> Summit Courier & Freight Ltd. | D35: =IF($K35="","",INDEX(AP_Register!$B$6:$B$33,$K35)) -> SCF-1190 | E35: =IF($K35="","",INDEX(AP_Register!$F$6:$F$33,$K35)) -> 46247 | F35: =IF($K35="","",INDEX(AP_Register!$AF$6:$AF$33,$K35)) -> 57 | G35: =IF($K35="","",INDEX(AP_Register!$X$6:$X$33,$K35)) -> 674.63 | H35: =IF($K35="","",INDEX(AP_Register!$S$6:$S$33,$K35)) -> Pending | I35: =IF($K35="","",INDEX(AP_Register!$U$6:$U$33,$K35)) -> Unpaid | J35: =IF($K35="","",IF(H35="On Hold","Resolve dispute with supplier",IF(H35="Pending","Chase approver",IF(H35="Rejected","Confirm with supplier",IF(INDEX(AP_Register!$AB$6:$AB$33,$K35)<>"","Obtain supporting docs, then pay",IF(INDEX(AP_Register!$AE$6:$AE$33,$K35)>0,"Clear exceptions, then pay","Schedule payment in next run")))))) -> Chase approver | K35: =IFERROR(MATCH(LARGE(AP_Register!$AG$6:$AG$33,3),AP_Register!$AG$6:$AG$33,0),"") -> 10
A36: =IF(K36="","",4) -> 4 | B36: =IF($K36="","",INDEX(AP_Register!$A$6:$A$33,$K36)) -> AP-0020 | C36: =IF($K36="","",INDEX(AP_Register!$C$6:$C$33,$K36)) -> Ridgeline Safety Supply Ltd. | D36: =IF($K36="","",INDEX(AP_Register!$B$6:$B$33,$K36)) -> RSS-20431A | E36: =IF($K36="","",INDEX(AP_Register!$F$6:$F$33,$K36)) -> 46261 | F36: =IF($K36="","",INDEX(AP_Register!$AF$6:$AF$33,$K36)) -> 43 | G36: =IF($K36="","",INDEX(AP_Register!$X$6:$X$33,$K36)) -> 2283.75 | H36: =IF($K36="","",INDEX(AP_Register!$S$6:$S$33,$K36)) -> Pending | I36: =IF($K36="","",INDEX(AP_Register!$U$6:$U$33,$K36)) -> Unpaid | J36: =IF($K36="","",IF(H36="On Hold","Resolve dispute with supplier",IF(H36="Pending","Chase approver",IF(H36="Rejected","Confirm with supplier",IF(INDEX(AP_Register!$AB$6:$AB$33,$K36)<>"","Obtain supporting docs, then pay",IF(INDEX(AP_Register!$AE$6:$AE$33,$K36)>0,"Clear exceptions, then pay","Schedule payment in next run")))))) -> Chase approver | K36: =IFERROR(MATCH(LARGE(AP_Register!$AG$6:$AG$33,4),AP_Register!$AG$6:$AG$33,0),"") -> 20
A37: =IF(K37="","",5) -> 5 | B37: =IF($K37="","",INDEX(AP_Register!$A$6:$A$33,$K37)) -> AP-0011 | C37: =IF($K37="","",INDEX(AP_Register!$C$6:$C$33,$K37)) -> Cinder Creek Fabrication Ltd. | D37: =IF($K37="","",INDEX(AP_Register!$B$6:$B$33,$K37)) -> CCF-0915 | E37: =IF($K37="","",INDEX(AP_Register!$F$6:$F$33,$K37)) -> 46261 | F37: =IF($K37="","",INDEX(AP_Register!$AF$6:$AF$33,$K37)) -> 43 | G37: =IF($K37="","",INDEX(AP_Register!$X$6:$X$33,$K37)) -> 11865 | H37: =IF($K37="","",INDEX(AP_Register!$S$6:$S$33,$K37)) -> Approved | I37: =IF($K37="","",INDEX(AP_Register!$U$6:$U$33,$K37)) -> Unpaid | J37: =IF($K37="","",IF(H37="On Hold","Resolve dispute with supplier",IF(H37="Pending","Chase approver",IF(H37="Rejected","Confirm with supplier",IF(INDEX(AP_Register!$AB$6:$AB$33,$K37)<>"","Obtain supporting docs, then pay",IF(INDEX(AP_Register!$AE$6:$AE$33,$K37)>0,"Clear exceptions, then pay","Schedule payment in next run")))))) -> Obtain supporting docs, then pay | K37: =IFERROR(MATCH(LARGE(AP_Register!$AG$6:$AG$33,5),AP_Register!$AG$6:$AG$33,0),"") -> 11
A38: =IF(K38="","",6) -> 6 | B38: =IF($K38="","",INDEX(AP_Register!$A$6:$A$33,$K38)) -> AP-0005 | C38: =IF($K38="","",INDEX(AP_Register!$C$6:$C$33,$K38)) -> Foothills Equipment Rentals Ltd. | D38: =IF($K38="","",INDEX(AP_Register!$B$6:$B$33,$K38)) -> FER-3307 | E38: =IF($K38="","",INDEX(AP_Register!$F$6:$F$33,$K38)) -> 46268 | F38: =IF($K38="","",INDEX(AP_Register!$AF$6:$AF$33,$K38)) -> 36 | G38: =IF($K38="","",INDEX(AP_Register!$X$6:$X$33,$K38)) -> 8820 | H38: =IF($K38="","",INDEX(AP_Register!$S$6:$S$33,$K38)) -> Approved | I38: =IF($K38="","",INDEX(AP_Register!$U$6:$U$33,$K38)) -> Unpaid | J38: =IF($K38="","",IF(H38="On Hold","Resolve dispute with supplier",IF(H38="Pending","Chase approver",IF(H38="Rejected","Confirm with supplier",IF(INDEX(AP_Register!$AB$6:$AB$33,$K38)<>"","Obtain supporting docs, then pay",IF(INDEX(AP_Register!$AE$6:$AE$33,$K38)>0,"Clear exceptions, then pay","Schedule payment in next run")))))) -> Schedule payment in next run | K38: =IFERROR(MATCH(LARGE(AP_Register!$AG$6:$AG$33,6),AP_Register!$AG$6:$AG$33,0),"") -> 5
A39: =IF(K39="","",7) -> 7 | B39: =IF($K39="","",INDEX(AP_Register!$A$6:$A$33,$K39)) -> AP-0012 | C39: =IF($K39="","",INDEX(AP_Register!$C$6:$C$33,$K39)) -> Clearwater Janitorial Ltd. | D39: =IF($K39="","",INDEX(AP_Register!$B$6:$B$33,$K39)) -> CJ-3402 | E39: =IF($K39="","",INDEX(AP_Register!$F$6:$F$33,$K39)) -> 46269 | F39: =IF($K39="","",INDEX(AP_Register!$AF$6:$AF$33,$K39)) -> 35 | G39: =IF($K39="","",INDEX(AP_Register!$X$6:$X$33,$K39)) -> 1942.5 | H39: =IF($K39="","",INDEX(AP_Register!$S$6:$S$33,$K39)) -> Pending | I39: =IF($K39="","",INDEX(AP_Register!$U$6:$U$33,$K39)) -> Unpaid | J39: =IF($K39="","",IF(H39="On Hold","Resolve dispute with supplier",IF(H39="Pending","Chase approver",IF(H39="Rejected","Confirm with supplier",IF(INDEX(AP_Register!$AB$6:$AB$33,$K39)<>"","Obtain supporting docs, then pay",IF(INDEX(AP_Register!$AE$6:$AE$33,$K39)>0,"Clear exceptions, then pay","Schedule payment in next run")))))) -> Chase approver | K39: =IFERROR(MATCH(LARGE(AP_Register!$AG$6:$AG$33,7),AP_Register!$AG$6:$AG$33,0),"") -> 12
A40: =IF(K40="","",8) -> 8 | B40: =IF($K40="","",INDEX(AP_Register!$A$6:$A$33,$K40)) -> AP-0014 | C40: =IF($K40="","",INDEX(AP_Register!$C$6:$C$33,$K40)) -> Ridgeline Safety Supply Ltd. | D40: =IF($K40="","",INDEX(AP_Register!$B$6:$B$33,$K40)) -> RSS-20466 | E40: =IF($K40="","",INDEX(AP_Register!$F$6:$F$33,$K40)) -> 46278 | F40: =IF($K40="","",INDEX(AP_Register!$AF$6:$AF$33,$K40)) -> 26 | G40: =IF($K40="","",INDEX(AP_Register!$X$6:$X$33,$K40)) -> 4851 | H40: =IF($K40="","",INDEX(AP_Register!$S$6:$S$33,$K40)) -> Approved | I40: =IF($K40="","",INDEX(AP_Register!$U$6:$U$33,$K40)) -> Unpaid | J40: =IF($K40="","",IF(H40="On Hold","Resolve dispute with supplier",IF(H40="Pending","Chase approver",IF(H40="Rejected","Confirm with supplier",IF(INDEX(AP_Register!$AB$6:$AB$33,$K40)<>"","Obtain supporting docs, then pay",IF(INDEX(AP_Register!$AE$6:$AE$33,$K40)>0,"Clear exceptions, then pay","Schedule payment in next run")))))) -> Schedule payment in next run | K40: =IFERROR(MATCH(LARGE(AP_Register!$AG$6:$AG$33,8),AP_Register!$AG$6:$AG$33,0),"") -> 14
A41: =IF(K41="","",9) -> 9 | B41: =IF($K41="","",INDEX(AP_Register!$A$6:$A$33,$K41)) -> AP-0024 | C41: =IF($K41="","",INDEX(AP_Register!$C$6:$C$33,$K41)) -> Prairie Fuel & Lube Inc. | D41: =IF($K41="","",INDEX(AP_Register!$B$6:$B$33,$K41)) -> PF-88391 | E41: =IF($K41="","",INDEX(AP_Register!$F$6:$F$33,$K41)) -> 46282 | F41: =IF($K41="","",INDEX(AP_Register!$AF$6:$AF$33,$K41)) -> 22 | G41: =IF($K41="","",INDEX(AP_Register!$X$6:$X$33,$K41)) -> 3276 | H41: =IF($K41="","",INDEX(AP_Register!$S$6:$S$33,$K41)) -> Approved | I41: =IF($K41="","",INDEX(AP_Register!$U$6:$U$33,$K41)) -> Unpaid | J41: =IF($K41="","",IF(H41="On Hold","Resolve dispute with supplier",IF(H41="Pending","Chase approver",IF(H41="Rejected","Confirm with supplier",IF(INDEX(AP_Register!$AB$6:$AB$33,$K41)<>"","Obtain supporting docs, then pay",IF(INDEX(AP_Register!$AE$6:$AE$33,$K41)>0,"Clear exceptions, then pay","Schedule payment in next run")))))) -> Obtain supporting docs, then pay | K41: =IFERROR(MATCH(LARGE(AP_Register!$AG$6:$AG$33,9),AP_Register!$AG$6:$AG$33,0),"") -> 24
A42: =IF(K42="","",10) -> 10 | B42: =IF($K42="","",INDEX(AP_Register!$A$6:$A$33,$K42)) -> AP-0019 | C42: =IF($K42="","",INDEX(AP_Register!$C$6:$C$33,$K42)) -> Northgate IT Services Inc. | D42: =IF($K42="","",INDEX(AP_Register!$B$6:$B$33,$K42)) -> NG-7752 | E42: =IF($K42="","",INDEX(AP_Register!$F$6:$F$33,$K42)) -> 46284 | F42: =IF($K42="","",INDEX(AP_Register!$AF$6:$AF$33,$K42)) -> 20 | G42: =IF($K42="","",INDEX(AP_Register!$X$6:$X$33,$K42)) -> 691.25 | H42: =IF($K42="","",INDEX(AP_Register!$S$6:$S$33,$K42)) -> Approved | I42: =IF($K42="","",INDEX(AP_Register!$U$6:$U$33,$K42)) -> Partially Paid | J42: =IF($K42="","",IF(H42="On Hold","Resolve dispute with supplier",IF(H42="Pending","Chase approver",IF(H42="Rejected","Confirm with supplier",IF(INDEX(AP_Register!$AB$6:$AB$33,$K42)<>"","Obtain supporting docs, then pay",IF(INDEX(AP_Register!$AE$6:$AE$33,$K42)>0,"Clear exceptions, then pay","Schedule payment in next run")))))) -> Schedule payment in next run | K42: =IFERROR(MATCH(LARGE(AP_Register!$AG$6:$AG$33,10),AP_Register!$AG$6:$AG$33,0),"") -> 19
A43: =IF(K43="","",11) -> 11 | B43: =IF($K43="","",INDEX(AP_Register!$A$6:$A$33,$K43)) -> AP-0021 | C43: =IF($K43="","",INDEX(AP_Register!$C$6:$C$33,$K43)) -> Summit Courier & Freight Ltd. | D43: =IF($K43="","",INDEX(AP_Register!$B$6:$B$33,$K43)) -> SCF-1241 | E43: =IF($K43="","",INDEX(AP_Register!$F$6:$F$33,$K43)) -> 46290 | F43: =IF($K43="","",INDEX(AP_Register!$AF$6:$AF$33,$K43)) -> 14 | G43: =IF($K43="","",INDEX(AP_Register!$X$6:$X$33,$K43)) -> 963.9 | H43: =IF($K43="","",INDEX(AP_Register!$S$6:$S$33,$K43)) -> Approved | I43: =IF($K43="","",INDEX(AP_Register!$U$6:$U$33,$K43)) -> Unpaid | J43: =IF($K43="","",IF(H43="On Hold","Resolve dispute with supplier",IF(H43="Pending","Chase approver",IF(H43="Rejected","Confirm with supplier",IF(INDEX(AP_Register!$AB$6:$AB$33,$K43)<>"","Obtain supporting docs, then pay",IF(INDEX(AP_Register!$AE$6:$AE$33,$K43)>0,"Clear exceptions, then pay","Schedule payment in next run")))))) -> Schedule payment in next run | K43: =IFERROR(MATCH(LARGE(AP_Register!$AG$6:$AG$33,11),AP_Register!$AG$6:$AG$33,0),"") -> 21
...

Sheet Expense_Claims
A1: SELF-DIRECTED PRACTICE PROJECT. All suppliers, invoices, amounts, employees and approvers are fictional and created for skills practice. This is not professional accounts payable experience. Policy limits are invented.
A2: Employee Expense Claims (fictional)
A4: Claim ID | B4: Employee | C4: Expense date | D4: Submitted date | E4: Category | F4: Description | G4: Amount claimed ($) | H4: Receipt attached (Y/N) | I4: Policy limit ($) | J4: Over limit? | K4: Missing receipt? | L4: Late submission? | M4: Possible duplicate? | N4: Approval status | O4: Reimbursable now ($) | P4: Action
A5: EC-001 | B5: E-Clark | C5: 46267 | D5: 46273 | E5: Meals | F5: Crew lunch, site visit | G5: 48.2 | H5: Y | I5: =INDEX(Lists!$B$18:$B$23,MATCH(E5,Lists!$A$18:$A$23,0)) -> 60 | J5: =IF(G5>I5,"OVER","") | K5: =IF(H5<>"Y","NO RECEIPT","") | L5: =IF(D5-C5>Lists!$B$25,"LATE","") | M5: =IF(COUNTIFS($B$5:B5,B5,$C$5:C5,C5,$G$5:G5,G5,$E$5:E5,E5)>1,"DUPLICATE","") | N5: Approved | O5: =IF(AND(N5="Approved",J5="",K5="",L5="",M5=""),G5,0) -> 48.2 | P5: =IF(N5="Rejected","Closed: rejected",IF(M5<>"","Reject: duplicate claim",IF(K5<>"","Hold: request receipt",IF(J5<>"","Hold: over limit, needs manager approval",IF(L5<>"","Hold: late, needs manager approval",IF(N5<>"Approved","Awaiting approval","Pay in next run")))))) -> Pay in next run
A6: EC-002 | B6: E-Clark | C6: 46268 | D6: 46273 | E6: Parking | F6: Downtown client meeting | G6: 32 | H6: Y | I6: =INDEX(Lists!$B$18:$B$23,MATCH(E6,Lists!$A$18:$A$23,0)) -> 40 | J6: =IF(G6>I6,"OVER","") | K6: =IF(H6<>"Y","NO RECEIPT","") | L6: =IF(D6-C6>Lists!$B$25,"LATE","") | M6: =IF(COUNTIFS($B$5:B6,B6,$C$5:C6,C6,$G$5:G6,G6,$E$5:E6,E6)>1,"DUPLICATE","") | N6: Approved | O6: =IF(AND(N6="Approved",J6="",K6="",L6="",M6=""),G6,0) -> 32 | P6: =IF(N6="Rejected","Closed: rejected",IF(M6<>"","Reject: duplicate claim",IF(K6<>"","Hold: request receipt",IF(J6<>"","Hold: over limit, needs manager approval",IF(L6<>"","Hold: late, needs manager approval",IF(N6<>"Approved","Awaiting approval","Pay in next run")))))) -> Pay in next run
A7: EC-003 | B7: E-Dube | C7: 46269 | D7: 46274 | E7: Lodging | F7: Hotel, Fort McMurray, 1 night | G7: 245 | H7: Y | I7: =INDEX(Lists!$B$18:$B$23,MATCH(E7,Lists!$A$18:$A$23,0)) -> 220 | J7: =IF(G7>I7,"OVER","") -> OVER | K7: =IF(H7<>"Y","NO RECEIPT","") | L7: =IF(D7-C7>Lists!$B$25,"LATE","") | M7: =IF(COUNTIFS($B$5:B7,B7,$C$5:C7,C7,$G$5:G7,G7,$E$5:E7,E7)>1,"DUPLICATE","") | N7: Pending | O7: =IF(AND(N7="Approved",J7="",K7="",L7="",M7=""),G7,0) -> 0 | P7: =IF(N7="Rejected","Closed: rejected",IF(M7<>"","Reject: duplicate claim",IF(K7<>"","Hold: request receipt",IF(J7<>"","Hold: over limit, needs manager approval",IF(L7<>"","Hold: late, needs manager approval",IF(N7<>"Approved","Awaiting approval","Pay in next run")))))) -> Hold: over limit, needs manager approval
A8: EC-004 | B8: E-Dube | C8: 46270 | D8: 46274 | E8: Meals | F8: Dinner, Fort McMurray | G8: 71.85 | H8: Y | I8: =INDEX(Lists!$B$18:$B$23,MATCH(E8,Lists!$A$18:$A$23,0)) -> 60 | J8: =IF(G8>I8,"OVER","") -> OVER | K8: =IF(H8<>"Y","NO RECEIPT","") | L8: =IF(D8-C8>Lists!$B$25,"LATE","") | M8: =IF(COUNTIFS($B$5:B8,B8,$C$5:C8,C8,$G$5:G8,G8,$E$5:E8,E8)>1,"DUPLICATE","") | N8: Pending | O8: =IF(AND(N8="Approved",J8="",K8="",L8="",M8=""),G8,0) -> 0 | P8: =IF(N8="Rejected","Closed: rejected",IF(M8<>"","Reject: duplicate claim",IF(K8<>"","Hold: request receipt",IF(J8<>"","Hold: over limit, needs manager approval",IF(L8<>"","Hold: late, needs manager approval",IF(N8<>"Approved","Awaiting approval","Pay in next run")))))) -> Hold: over limit, needs manager approval
A9: EC-005 | B9: E-Evans | C9: 46244 | D9: 46279 | E9: Supplies | F9: Hand tools, small | G9: 96.4 | H9: Y | I9: =INDEX(Lists!$B$18:$B$23,MATCH(E9,Lists!$A$18:$A$23,0)) -> 150 | J9: =IF(G9>I9,"OVER","") | K9: =IF(H9<>"Y","NO RECEIPT","") | L9: =IF(D9-C9>Lists!$B$25,"LATE","") -> LATE | M9: =IF(COUNTIFS($B$5:B9,B9,$C$5:C9,C9,$G$5:G9,G9,$E$5:E9,E9)>1,"DUPLICATE","") | N9: Pending | O9: =IF(AND(N9="Approved",J9="",K9="",L9="",M9=""),G9,0) -> 0 | P9: =IF(N9="Rejected","Closed: rejected",IF(M9<>"","Reject: duplicate claim",IF(K9<>"","Hold: request receipt",IF(J9<>"","Hold: over limit, needs manager approval",IF(L9<>"","Hold: late, needs manager approval",IF(N9<>"Approved","Awaiting approval","Pay in next run")))))) -> Hold: late, needs manager approval
A10: EC-006 | B10: E-Evans | C10: 46275 | D10: 46279 | E10: Taxi / Rideshare | F10: Airport to office | G10: 54.3 | H10: N | I10: =INDEX(Lists!$B$18:$B$23,MATCH(E10,Lists!$A$18:$A$23,0)) -> 80 | J10: =IF(G10>I10,"OVER","") | K10: =IF(H10<>"Y","NO RECEIPT","") -> NO RECEIPT | L10: =IF(D10-C10>Lists!$B$25,"LATE","") | M10: =IF(COUNTIFS($B$5:B10,B10,$C$5:C10,C10,$G$5:G10,G10,$E$5:E10,E10)>1,"DUPLICATE","") | N10: Pending | O10: =IF(AND(N10="Approved",J10="",K10="",L10="",M10=""),G10,0) -> 0 | P10: =IF(N10="Rejected","Closed: rejected",IF(M10<>"","Reject: duplicate claim",IF(K10<>"","Hold: request receipt",IF(J10<>"","Hold: over limit, needs manager approval",IF(L10<>"","Hold: late, needs manager approval",IF(N10<>"Approved","Awaiting approval","Pay in next run")))))) -> Hold: request receipt
A11: EC-007 | B11: E-Fraser | C11: 46276 | D11: 46280 | E11: Client Entertainment | F11: Client lunch, 4 people | G11: 182 | H11: Y | I11: =INDEX(Lists!$B$18:$B$23,MATCH(E11,Lists!$A$18:$A$23,0)) -> 200 | J11: =IF(G11>I11,"OVER","") | K11: =IF(H11<>"Y","NO RECEIPT","") | L11: =IF(D11-C11>Lists!$B$25,"LATE","") | M11: =IF(COUNTIFS($B$5:B11,B11,$C$5:C11,C11,$G$5:G11,G11,$E$5:E11,E11)>1,"DUPLICATE","") | N11: Approved | O11: =IF(AND(N11="Approved",J11="",K11="",L11="",M11=""),G11,0) -> 182 | P11: =IF(N11="Rejected","Closed: rejected",IF(M11<>"","Reject: duplicate claim",IF(K11<>"","Hold: request receipt",IF(J11<>"","Hold: over limit, needs manager approval",IF(L11<>"","Hold: late, needs manager approval",IF(N11<>"Approved","Awaiting approval","Pay in next run")))))) -> Pay in next run
A12: EC-008 | B12: E-Fraser | C12: 46276 | D12: 46280 | E12: Client Entertainment | F12: Client lunch, 4 people | G12: 182 | H12: Y | I12: =INDEX(Lists!$B$18:$B$23,MATCH(E12,Lists!$A$18:$A$23,0)) -> 200 | J12: =IF(G12>I12,"OVER","") | K12: =IF(H12<>"Y","NO RECEIPT","") | L12: =IF(D12-C12>Lists!$B$25,"LATE","") | M12: =IF(COUNTIFS($B$5:B12,B12,$C$5:C12,C12,$G$5:G12,G12,$E$5:E12,E12)>1,"DUPLICATE","") -> DUPLICATE | N12: Pending | O12: =IF(AND(N12="Approved",J12="",K12="",L12="",M12=""),G12,0) -> 0 | P12: =IF(N12="Rejected","Closed: rejected",IF(M12<>"","Reject: duplicate claim",IF(K12<>"","Hold: request receipt",IF(J12<>"","Hold: over limit, needs manager approval",IF(L12<>"","Hold: late, needs manager approval",IF(N12<>"Approved","Awaiting approval","Pay in next run")))))) -> Reject: duplicate claim
A13: EC-009 | B13: E-Gill | C13: 46279 | D13: 46281 | E13: Meals | F13: Working lunch | G13: 38.75 | H13: Y | I13: =INDEX(Lists!$B$18:$B$23,MATCH(E13,Lists!$A$18:$A$23,0)) -> 60 | J13: =IF(G13>I13,"OVER","") | K13: =IF(H13<>"Y","NO RECEIPT","") | L13: =IF(D13-C13>Lists!$B$25,"LATE","") | M13: =IF(COUNTIFS($B$5:B13,B13,$C$5:C13,C13,$G$5:G13,G13,$E$5:E13,E13)>1,"DUPLICATE","") | N13: Approved | O13: =IF(AND(N13="Approved",J13="",K13="",L13="",M13=""),G13,0) -> 38.75 | P13: =IF(N13="Rejected","Closed: rejected",IF(M13<>"","Reject: duplicate claim",IF(K13<>"","Hold: request receipt",IF(J13<>"","Hold: over limit, needs manager approval",IF(L13<>"","Hold: late, needs manager approval",IF(N13<>"Approved","Awaiting approval","Pay in next run")))))) -> Pay in next run
